Workbook
Name UPDATE: 'Data Sheet'!$E$1

Sheet Comps Valuation
B2: Comparable Companies Valuation
C4: Market Data | K4: Financials | O4: Valuation
B5: Company | C5: Ticker | D5: Share Price | E5: Shares Outstaning | F5: Equit Value | G5: Net Debt | H5: Enterprise Value | K5: Revenue | L5: EBITDA | M5: Net Income | O5: EV/ Revnue | P5: EV/ EBITDA | Q5: P/E
B6: =Data!C3 -> Asian Paints | C6: ASIANPAINT | D6: =Data!D3 -> 2536.1 | E6: =Data!E3 -> 95.92 | F6: =D6*E6 -> 243262.71 | G6: =Data!G3 -> 2290.29 | H6: =Data!I3 -> 244770.45 | K6: =Data!J3 -> 33874.44 | L6: =Data!K3 -> 6687.7172 | M6: =Data!M3 -> 3639.97 | O6: =$H6/K6 -> 7.2258154 | P6: =$H6/L6 -> 36.6 | Q6: =F6/M6 -> 66.830966
B7: =Data!C4 -> Berger Paints | C7: BERGEPAINT | D7: =Data!D4 -> 532.5 | E7: =Data!E4 -> 116.59 | F7: =D7*E7 -> 62084.175 | G7: =Data!G4 -> 670.27 | H7: =Data!I4 -> 62253.72 | K7: =Data!J4 -> 11654.46 | L7: =Data!K4 -> 1985.7646 | M7: =Data!M4 -> 1143.82 | O7: =$H7/K7 -> 5.341622 | P7: =$H7/L7 -> 31.35 | Q7: =F7/M7 -> 54.277924
B8: =Data!C5 -> Kansai Nerolac | C8: KANSAINER | D8: =Data!D5 -> 245.85 | E8: =Data!E5 -> 80.85 | F8: =D8*E8 -> 19876.972 | G8: =Data!G5 -> 296.39 | H8: =Data!I5 -> 19883.37 | K8: =Data!J5 -> 7851.94 | L8: =Data!K5 -> 1073.6161 | M8: =Data!M5 -> 1100.05 | O8: =$H8/K8 -> 2.5322876 | P8: =$H8/L8 -> 18.52 | Q8: =F8/M8 -> 18.069154
B9: =Data!C6 -> Akzo Nobel | C9: AKZOINDIA | D9: =Data!D6 -> 3389.75 | E9: =Data!E6 -> 4.55 | F9: =D9*E9 -> 15423.362 | G9: =Data!G6 -> 62.1 | H9: =Data!I6 -> 15199.63 | K9: =Data!J6 -> 4050 | L9: =Data!K6 -> 633.58191 | M9: =Data!M6 -> 405 | O9: =$H9/K9 -> 3.7529951 | P9: =$H9/L9 -> 23.99 | Q9: =F9/M9 -> 38.082377
B10: =Data!C7 -> Indigo Paints | C10: INDIGOPNTS | D10: =Data!D7 -> 1130 | E10: =Data!E7 -> 4.76 | F10: =D10*E10 -> 5378.8 | G10: =Data!G7 -> 19.7 | H10: =Data!I7 -> 5365.34 | K10: =Data!J7 -> 1278.1 | L10: =Data!K7 -> 248.51042 | M10: =Data!M7 -> 143.84 | O10: =$H10/K10 -> 4.1979031 | P10: =$H10/L10 -> 21.59 | Q10: =F10/M10 -> 37.394327
B11: =Data!C8 -> Sirca Paints | C11: SIRCA | D11: =Data!D8 -> 461.75 | E11: =Data!E8 -> 5.48 | F11: =D11*E11 -> 2530.39 | G11: =Data!G8 -> 8.33 | H11: =Data!I8 -> 2484.95 | K11: =Data!J8 -> 409.37 | L11: =Data!K8 -> 79.901929 | M11: =Data!M8 -> 53.05 | O11: =$H11/K11 -> 6.070181 | P11: =$H11/L11 -> 31.1 | Q11: =F11/M11 -> 47.698209
B12: =Data!C9 -> Shalimar Paints | C12: SHALPAINTS | D12: =Data!D9 -> 74 | E12: =Data!E9 -> 8.37 | F12: =D12*E12 -> 619.38 | G12: =Data!G9 -> 163.86 | H12: =Data!I9 -> 737.89 | K12: =Data!J9 -> 624.19 | L12: =Data!K9 -> -32.520494 | M12: =Data!M9 -> -69.79 | O12: =$H12/K12 -> 1.1821561 | P12: =$H12/L12 -> -22.69 | Q12: =F12/M12 -> -8.8749104
B13: =Data!C10 -> Kamdhenu Venture | C13: KAMOPAINTS | D13: =Data!D10 -> 9.06 | E13: =Data!E10 -> 31.44 | F13: =D13*E13 -> 284.8464 | G13: =Data!G10 -> 26.98 | H13: =Data!I10 -> 305.89 | K13: =Data!J10 -> 261.89 | L13: =Data!K10 -> 16.770285 | M13: =Data!M10 -> 5.94 | O13: =$H13/K13 -> 1.1680095 | P13: =$H13/L13 -> 18.24 | Q13: =F13/M13 -> 47.953939
B14: =Data!C11 -> Siddhika Coatins | C14: SIDDHIKA | D14: =Data!D11 -> 200.5 | E14: =Data!E11 -> 0.62 | F14: =D14*E14 -> 124.31 | G14: =Data!G11 -> 0 | H14: =Data!I11 -> 118.13 | K14: =Data!J11 -> 48.01 | L14: =Data!K11 -> 10.435512 | M14: =Data!M11 -> 8.03 | O14: =$H14/K14 -> 2.4605291 | P14: =$H14/L14 -> 11.32 | Q14: =F14/M14 -> 15.480697
B15: =Data!C12 -> Retina Paints | D15: =Data!D12 -> 73 | E15: =Data!E12 -> 1.53 | F15: =D15*E15 -> 111.69 | G15: =Data!G12 -> 8.12 | H15: =Data!I12 -> 119.78 | K15: =Data!J12 -> 11.66 | L15: =Data!K12 -> 2.0198988 | M15: =Data!M12 -> 0.74 | O15: =$H15/K15 -> 10.272727 | P15: =$H15/L15 -> 59.3 | Q15: =F15/M15 -> 150.93243
B17: High | O17: =MAX(O6:O15) -> 10.272727 | P17: =MAX(P6:P15) -> 59.3 | Q17: =MAX(Q6:Q15) -> 150.93243
B18: 75th Percentile | O18: =QUARTILE(O6:O15,) -> 1.1680095 | P18: =QUARTILE(P6:P15,) -> -22.69 | Q18: =QUARTILE(Q6:Q15,) -> -8.8749104
B19: Average | O19: =AVERAGE(O6:O15) -> 4.4204226 | P19: =AVERAGE(P6:P15) -> 22.932 | Q19: =AVERAGE(Q6:Q15) -> 46.784512
B20: Median | O20: =MEDIAN(O6:O15) -> 3.9754491 | P20: =MEDIAN(P6:P15) -> 22.79 | Q20: =MEDIAN(Q6:Q15) -> 42.890293
B21: 25th Percentile | O21: =QUARTILE(O6:O15,1) -> 2.4784687 | P21: =QUARTILE(P6:P15,1) -> 18.31 | Q21: =QUARTILE(Q6:Q15,1) -> 22.900447
B22: Low | O22: =MIN(O6:O15) -> 1.1680095 | P22: =MIN(P6:P15) -> -22.69 | Q22: =MIN(Q6:Q15) -> -8.8749104
B24: =$B$6&" Comparable Valuation" -> Asian Paints Comparable Valuation | O24: EV/ Revnue | P24: EV/ EBITDA | Q24: P/E
B26: Implied Enterprise Value | O26: =K6 -> 33874.44 | P26: =L6 -> 6687.7172 | Q26: =Q28+Q27 -> 158409.67
B27: Debt | O27: =$G$6 -> 2290.29 | P27: =$G$6 -> 2290.29 | Q27: =$G$6 -> 2290.29
B28: Implied Market Value | O28: =O26-O27 -> 31584.15 | P28: =P26-P27 -> 4397.4272 | Q28: =M6*Q20 -> 156119.38
B29: Shares Outstanding | O29: =$E$6 -> 95.92 | P29: =$E$6 -> 95.92 | Q29: =$E$6 -> 95.92
B30: Implied Market Value Per Share | O30: =O28/O29 -> 329.27596 | P30: =P28/P29 -> 45.844737 | Q30: =Q28/Q29 -> 1627.5999
O32: =IF(O30>D6,"Undervalued","Overvalued") -> Overvalued | P32: =IF(P30>E6,"Undervalued","Overvalued") -> Overvalued | Q32: =IF(Q30>F6,"Undervalued","Overvalued") -> Overvalued

Sheet Football Field
C2: Football Field Analysis
B20: Data Table -
M21: 1771
M22: 0.1105
C23: Open Low | D23: Low | E23: Open High | F23: High | M23: 0.045
B24: Comps | C24: 45.8 | D24: 45.8 | E24: 329 | F24: 329
B25: Bear Case | C25: 202 | D25: 202 | E25: 229 | F25: 229 | M25: =M21/M22-M23 -> 16027.104
B26: Base Case | C26: 246 | D26: 246 | E26: 293 | F26: 293
B27: Bull Case | C27: 229 | D27: 229 | E27: 267 | F27: 267
B28: 52W H/L | C28: 198 | D28: 198 | E28: 300 | F28: 300

Sheet DCF
B2: ="Discounted Cash-Flow - "&'Profit & Loss'!$A$1 -> Discounted Cash-Flow - ASIAN PAINTS LTD
B5: Calculating PV of FCFF | G5: =FS!J5 -> 44651 | H5: =FS!K5 -> 45016 | I5: =FS!L5 -> 45382 | J5: =FS!M5 -> 45747 | K5: =J5+365 -> 46112 | L5: =K5+365 -> 46477 | M5: =L5+366 -> 46843 | N5: =M5+365 -> 47208 | O5: =N5+365 -> 47573
B7: EBIT | G7: =FS!D27 -> 2662.85 | H7: =FS!E27 -> 2996.87 | I7: =FS!F27 -> 3179.95 | J7: =FS!G27 -> 3416.57 | K7: =J7*(1+$C$23) -> 4364.077 | L7: =K7*(1+$C$23) -> 5574.3533 | M7: =L7*(1+$C$23) -> 7120.2719 | N7: =M7*(1+$C$23) -> 9094.9153 | O7: =N7*(1+$C$23) -> 11617.181
B9: Tax Rate | G9: 0.3 | H9: =G9 -> 0.3 | I9: =H9 -> 0.3 | J9: =I9 -> 0.3 | K9: =J9 -> 0.3 | L9: =K9 -> 0.3 | M9: =L9 -> 0.3 | N9: =M9 -> 0.3 | O9: =N9 -> 0.3
B11: EBIT*(1-T) | G11: =G7*(1-G9) -> 1863.995 | H11: =H7*(1-H9) -> 2097.809 | I11: =I7*(1-I9) -> 2225.965 | J11: =J7*(1-J9) -> 2391.599 | K11: =K7*(1-K9) -> 3054.8539 | L11: =L7*(1-L9) -> 3902.0473 | M11: =M7*(1-M9) -> 4984.1903 | N11: =N7*(1-N9) -> 6366.4407 | O11: =O7*(1-O9) -> 8132.0265
B13: Less: Reinvestment Rate | G13: ='Intrinsic Growth'!$G$52 -> 0.88786204 | H13: ='Intrinsic Growth'!$G$52 -> 0.88786204 | I13: ='Intrinsic Growth'!$G$52 -> 0.88786204 | J13: ='Intrinsic Growth'!$G$52 -> 0.88786204 | K13: ='Intrinsic Growth'!$G$52 -> 0.88786204 | L13: ='Intrinsic Growth'!$G$52 -> 0.88786204 | M13: ='Intrinsic Growth'!$G$52 -> 0.88786204 | N13: ='Intrinsic Growth'!$G$52 -> 0.88786204 | O13: ='Intrinsic Growth'!$G$52 -> 0.88786204
B15: Free Cash Flow to Firm (FCFF) | G15: =G11*(1-G13) -> 209.02459 | H15: =H11*(1-H13) -> 235.24401 | I15: =I11*(1-I13) -> 249.61517 | J15: =J11*(1-J13) -> 268.18903 | K15: =K11*(1-K13) -> 342.56508 | L15: =L11*(1-L13) -> 437.56761 | M15: =M11*(1-M13) -> 558.91692 | N15: =N11*(1-N13) -> 713.91965 | O15: =O11*(1-O13) -> 911.90883
B17: Mid Year Convention | K17: 0.5 | L17: =K17+1 -> 1.5 | M17: =L17+1 -> 2.5 | N17: =M17+1 -> 3.5 | O17: =N17+1 -> 4.5
B19: Discounting Factor | K19: =1/(1+$D$24)^K17 -> 1 | L19: =1/(1+$D$24)^L17 -> 1 | M19: =1/(1+$D$24)^M17 -> 1 | N19: =1/(1+$D$24)^N17 -> 1 | O19: =1/(1+$D$24)^O17 -> 1
B21: PV of FCFF | K21: =K15*K19 -> 342.56508 | L21: =L15*L19 -> 437.56761 | M21: =M15*M19 -> 558.91692 | N21: =N15*N19 -> 713.91965 | O21: =O15*O19 -> 911.90883
B23: Expected Growth Rate | C23: ='Intrinsic Growth'!G60 -> 0.27732698
B24: Terminal Growth Rate | C24: 0.065
B26: Calculating Terminal Value
B28: FCFF (n+1) | E28: =O15*(1+C23) -> 1164.8058
B29: WACC | E29: 0.1205
B30: =B24 -> Terminal Growth Rate | E30: 0.065
B32: Terminal Value | E32: =E28/E29-E30 -> 9666.3728
B34: Calculating Equity Value Per Share
B36: PV of FCFF | E36: =SUM(K21:O21) -> 2964.8781
B37: PV of Terminal Value | E37: =E32*O19 -> 9666.3728
B38: Enterprise Value | E38: =SUM(E36:E37) -> 12631.251
B40: Add: Cash | E40: ='Data Sheet'!K69 -> 781.98
B41: Less: Debt | E41: =SUM('Raw FS'!N7:N8) -> 864
B42: Equity Value | E42: =E38+E40-E41 -> 12549.231
B43: No. of Shares | E43: ='Data Sheet'!B6 -> 95.919781
B45: Equity Value per Share | E45: =E42/E43 -> 130.83048
B47: Share Price | E47: 2541
B48: Discount/Premium | E48: =E47/E45 -> 19.42208

Sheet CSS
B2: ='Profit & Loss'!$A$1 -> ASIAN PAINTS LTD
B5: ="Common Size Income Statement - "& 'Profit & Loss'!$A$1 -> Common Size Income Statement - ASIAN PAINTS LTD
B7: Particulars | C7: =FS!D5 -> 42460 | D7: =FS!E5 -> 42825 | E7: =FS!F5 -> 43190 | F7: =FS!G5 -> 43555 | G7: =FS!H5 -> 43921 | H7: =FS!I5 -> 44286 | I7: =FS!J5 -> 44651 | J7: =FS!K5 -> 45016 | ... L7: =FS!M5 -> 45747
B9: =FS!B9 -> Sales | C9: =FS!D9/FS!D$9 -> 1 | D9: =FS!E9/FS!E$9 -> 1 | E9: =FS!F9/FS!F$9 -> 1 | F9: =FS!G9/FS!G$9 -> 1 | G9: =FS!H9/FS!H$9 -> 1 | H9: =FS!I9/FS!I$9 -> 1 | I9: =FS!J9/FS!J$9 -> 1 | J9: =FS!K9/FS!K$9 -> 1 | ... L9: =FS!M9/FS!M$9 -> 1
B10: =FS!B12 -> COGS | C10: =FS!D12/FS!D$9 -> 0.55395197 | D10: =FS!E12/FS!E$9 -> 0.5771329 | E10: =FS!F12/FS!F$9 -> 0.59866564 | F10: =FS!G12/FS!G$9 -> 0.60618717 | G10: =FS!H12/FS!H$9 -> 0.58317769 | H10: =FS!I12/FS!I$9 -> 0.57512001 | I10: =FS!J12/FS!J$9 -> 0.64588087 | J10: =FS!K12/FS!K$9 -> 0.63007186 | ... L10: =FS!M12/FS!M$9 -> 0.5938688
B11: =FS!B15 -> Gross Profit | C11: =FS!D15/FS!D$9 -> 0.44604803 | D11: =FS!E15/FS!E$9 -> 0.4228671 | E11: =FS!F15/FS!F$9 -> 0.40133436 | F11: =FS!G15/FS!G$9 -> 0.39381283 | G11: =FS!H15/FS!H$9 -> 0.41682231 | H11: =FS!I15/FS!I$9 -> 0.42487999 | I11: =FS!J15/FS!J$9 -> 0.35411913 | J11: =FS!K15/FS!K$9 -> 0.36992814 | ... L11: =FS!M15/FS!M$9 -> 0.4061312
B12: =FS!B18 -> S&G Expenses | C12: =FS!D18/FS!D$9 -> 0.25918177 | D12: =FS!E18/FS!E$9 -> 0.26730465 | E12: =FS!F18/FS!F$9 -> 0.11403039 | F12: =FS!G18/FS!G$9 -> 0.10878825 | G12: =FS!H18/FS!H$9 -> 0.096800544 | H12: =FS!I18/FS!I$9 -> 0.088152651 | I12: =FS!J18/FS!J$9 -> 0.090927272 | J12: =FS!K18/FS!K$9 -> 0.08899697 | ... L12: =FS!M18/FS!M$9 -> 0.10395681
B13: =FS!B21 -> EBITDA | C13: =FS!D21/FS!D$9 -> 0.19094292 | D13: =FS!E21/FS!E$9 -> 0.19876258 | E13: =FS!F21/FS!F$9 -> 0.19043659 | F13: =FS!G21/FS!G$9 -> 0.19568163 | G13: =FS!H21/FS!H$9 -> 0.20566863 | H13: =FS!I21/FS!I$9 -> 0.22362856 | I13: =FS!J21/FS!J$9 -> 0.16506525 | J13: =FS!K21/FS!K$9 -> 0.18150467 | ... L13: =FS!M21/FS!M$9 -> 0.17714497
B14: =FS!B24 -> Depriciation | C14: =FS!D24/FS!D$9 -> 0.019309827 | D14: =FS!E24/FS!E$9 -> 0.022227475 | E14: =FS!F24/FS!F$9 -> 0.021425239 | F14: =FS!G24/FS!G$9 -> 0.03233554 | G14: =FS!H24/FS!H$9 -> 0.038617107 | H14: =FS!I24/FS!I$9 -> 0.036442576 | I14: =FS!J24/FS!J$9 -> 0.028052374 | J14: =FS!K24/FS!K$9 -> 0.024878373 | ... L14: =FS!M24/FS!M$9 -> 0.030270498
B15: =FS!B27 -> EBIT | C15: =FS!D27/FS!D$9 -> 0.18658528 | D15: =FS!E27/FS!E$9 -> 0.19896906 | E15: =FS!F27/FS!F$9 -> 0.18900654 | F15: =FS!G27/FS!G$9 -> 0.1775752 | G15: =FS!H27/FS!H$9 -> 0.18461847 | H15: =FS!I27/FS!I$9 -> 0.20246039 | I15: =FS!J27/FS!J$9 -> 0.14718012 | J15: =FS!K27/FS!K$9 -> 0.16913652 | ... L15: =FS!M27/FS!M$9 -> 0.15720373
B16: =FS!B30 -> Interest | C16: =FS!D30/FS!D$9 -> 0.0034334187 | D16: =FS!E30/FS!E$9 -> 0.0024784242 | E16: =FS!F30/FS!F$9 -> 0.0024648505 | F16: =FS!G30/FS!G$9 -> 0.0057416452 | G16: =FS!H30/FS!H$9 -> 0.0050630218 | H16: =FS!I30/FS!I$9 -> 0.0042200933 | I16: =FS!J30/FS!J$9 -> 0.0032785499 | J16: =FS!K30/FS!K$9 -> 0.0041883417 | ... L16: =FS!M30/FS!M$9 -> 0.0066956451
B17: =FS!B33 -> EBT | C17: =FS!D33/FS!D$9 -> 0.18315186 | D17: =FS!E33/FS!E$9 -> 0.19649064 | E17: =FS!F33/FS!F$9 -> 0.18654169 | F17: =FS!G33/FS!G$9 -> 0.17183356 | G17: =FS!H33/FS!H$9 -> 0.17955545 | H17: =FS!I33/FS!I$9 -> 0.1982403 | I17: =FS!J33/FS!J$9 -> 0.14390157 | J17: =FS!K33/FS!K$9 -> 0.16494818 | ... L17: =FS!M33/FS!M$9 -> 0.15050809
B18: =FS!B36 -> Tax | C18: =FS!D36/FS!D$9 -> 0.059173219 | D18: =FS!E36/FS!E$9 -> 0.062627183 | E18: =FS!F36/FS!F$9 -> 0.061871491 | F18: =FS!G36/FS!G$9 -> 0.05707134 | G18: =FS!H36/FS!H$9 -> 0.042295751 | H18: =FS!I36/FS!I$9 -> 0.05055085 | I18: =FS!J36/FS!J$9 -> 0.03789902 | J18: =FS!K36/FS!K$9 -> 0.043304177 | ... L18: =FS!M36/FS!M$9 -> 0.041095252
B19: =FS!B39 -> Net Profit | C19: =FS!D39/FS!D$9 -> 0.12228296 | D19: =FS!E39/FS!E$9 -> 0.1287632 | E19: =FS!F39/FS!F$9 -> 0.12118779 | F19: =FS!G39/FS!G$9 -> 0.1120533 | G19: =FS!H39/FS!H$9 -> 0.13384476 | H19: =FS!I39/FS!I$9 -> 0.14458252 | I19: =FS!J39/FS!J$9 -> 0.10413872 | J19: =FS!K39/FS!K$9 -> 0.11906691 | ... L19: =FS!M39/FS!M$9 -> 0.10815995
B22: ="Common Size Balance Sheet - "& 'Profit & Loss'!$A$1 -> Common Size Balance Sheet - ASIAN PAINTS LTD
B24: Particulars | C24: =FS!D5 -> 42460 | D24: =FS!E5 -> 42825 | E24: =FS!F5 -> 43190 | F24: =FS!G5 -> 43555 | G24: =FS!H5 -> 43921 | H24: =FS!I5 -> 44286 | I24: =FS!J5 -> 44651 | J24: =FS!K5 -> 45016 | ... L24: =FS!M5 -> 45747
B26: =FS!B55 -> Equity Share Capital | C26: =FS!D55/FS!D$59 -> 0.0090841678 | D26: =FS!E55/FS!E$59 -> 0.0077322476 | E26: =FS!F55/FS!F$59 -> 0.0069691677 | F26: =FS!G55/FS!G$59 -> 0.0059031906 | G26: =FS!H55/FS!H$59 -> 0.0059437463 | H26: =FS!I55/FS!I$59 -> 0.004712277 | I26: =FS!J55/FS!J$59 -> 0.004177986 | J26: =FS!K55/FS!K$59 -> 0.0037208104 | ... L26: =FS!M55/FS!M$59 -> 0.0031599147
B27: =FS!B56 -> Reserves | C27: =FS!D56/FS!D$59 -> 0.60885328 | D27: =FS!E56/FS!E$59 -> 0.60522813 | E27: =FS!F56/FS!F$59 -> 0.60408487 | F27: =FS!G56/FS!G$59 -> 0.57694149 | G27: =FS!H56/FS!H$59 -> 0.62177833 | H27: =FS!I56/FS!I$59 -> 0.62442435 | I27: =FS!J56/FS!J$59 -> 0.59741193 | J27: =FS!K56/FS!K$59 -> 0.61663007 | ... L27: =FS!M56/FS!M$59 -> 0.6359325
B28: =FS!B57 -> Borrowings | C28: =FS!D57/FS!D$59 -> 0.030617396 | D28: =FS!E57/FS!E$59 -> 0.045169804 | E28: =FS!F57/FS!F$59 -> 0.038756913 | F28: =FS!G57/FS!G$59 -> 0.081211951 | G28: =FS!H57/FS!H$59 -> 0.069308593 | H28: =FS!I57/FS!I$59 -> 0.053701879 | I28: =FS!J57/FS!J$59 -> 0.069119709 | J28: =FS!K57/FS!K$59 -> 0.074967813 | ... L28: =FS!M57/FS!M$59 -> 0.075449552
B29: =FS!B58 -> Other Liabilities | C29: =FS!D58/FS!D$59 -> 0.35144516 | D29: =FS!E58/FS!E$59 -> 0.34186981 | E29: =FS!F58/FS!F$59 -> 0.35018905 | F29: =FS!G58/FS!G$59 -> 0.33594337 | G29: =FS!H58/FS!H$59 -> 0.30296933 | H29: =FS!I58/FS!I$59 -> 0.31716149 | I29: =FS!J58/FS!J$59 -> 0.32929037 | J29: =FS!K58/FS!K$59 -> 0.30468131 | ... L29: =FS!M58/FS!M$59 -> 0.28545803
B30: =FS!B59 -> Total Liabilities | C30: =FS!D59/FS!D$59 -> 1 | D30: =FS!E59/FS!E$59 -> 1 | E30: =FS!F59/FS!F$59 -> 1 | F30: =FS!G59/FS!G$59 -> 1 | G30: =FS!H59/FS!H$59 -> 1 | H30: =FS!I59/FS!I$59 -> 1 | I30: =FS!J59/FS!J$59 -> 1 | J30: =FS!K59/FS!K$59 -> 1 | ... L30: =FS!M59/FS!M$59 -> 1
B32: =FS!B61 -> Net Block | C32: =FS!D61/FS!D$72 -> 0.32354771 | D32: =FS!E61/FS!E$72 -> 0.26631918 | E32: =FS!F61/FS!F$72 -> 0.27116979 | F32: =FS!G61/FS!G$72 -> 0.39981685 | G32: =FS!H61/FS!H$72 -> 0.38866784 | H32: =FS!I61/FS!I$72 -> 0.28781244 | I32: =FS!J61/FS!J$72 -> 0.24039362 | J32: =FS!K61/FS!K$72 -> 0.22384057 | ... L32: =FS!M61/FS!M$72 -> 0.30373988
B33: =FS!B62 -> Capital Work in Progress | C33: =FS!D62/FS!D$72 -> 0.010094677 | D33: =FS!E62/FS!E$72 -> 0.020760665 | E33: =FS!F62/FS!F$72 -> 0.10208973 | F33: =FS!G62/FS!G$72 -> 0.01290369 | G33: =FS!H62/FS!H$72 -> 0.0086900645 | H33: =FS!I62/FS!I$72 -> 0.0089892873 | I33: =FS!J62/FS!J$72 -> 0.018574005 | J33: =FS!K62/FS!K$72 -> 0.039550679 | ... L33: =FS!M62/FS!M$72 -> 0.041326953
B34: =FS!B63 -> Investments | C34: =FS!D63/FS!D$72 -> 0.25685409 | D34: =FS!E63/FS!E$72 -> 0.21378068 | E34: =FS!F63/FS!F$72 -> 0.15553479 | F34: =FS!G63/FS!G$72 -> 0.15807775 | G34: =FS!H63/FS!H$72 -> 0.12509938 | H34: =FS!I63/FS!I$72 -> 0.23270552 | I34: =FS!J63/FS!J$72 -> 0.14145262 | J34: =FS!K63/FS!K$72 -> 0.165315 | ... L34: =FS!M63/FS!M$72 -> 0.15564853
B35: =FS!B64 -> Other Assets | C35: =FS!D64/FS!D$72 -> 0.049800029 | D35: =FS!E64/FS!E$72 -> 0.013495964 | E35: =FS!F64/FS!F$72 -> 0.031306036 | F35: =FS!G64/FS!G$72 -> 0.024709456 | G35: =FS!H64/FS!H$72 -> -0.018324486 | H35: =FS!I64/FS!I$72 -> 0.002709854 | I35: =FS!J64/FS!J$72 -> -0.10734314 | J35: =FS!K64/FS!K$72 -> -0.11610465 | ... L35: =FS!M64/FS!M$72 -> -0.078001993
B36: =FS!B65 -> Total Non-Current Assets (A) | C36: =FS!D65/FS!D$72 -> 0.6402965 | D36: =FS!E65/FS!E$72 -> 0.51435649 | E36: =FS!F65/FS!F$72 -> 0.56010035 | F36: =FS!G65/FS!G$72 -> 0.59550774 | G36: =FS!H65/FS!H$72 -> 0.5041328 | H36: =FS!I65/FS!I$72 -> 0.5322171 | I36: =FS!J65/FS!J$72 -> 0.2930771 | J36: =FS!K65/FS!K$72 -> 0.31260161 | ... L36: =FS!M65/FS!M$72 -> 0.42271337
B38: =FS!B67 -> Working Capital | C38: =FS!D67/FS!D$72 -> 0.058058363 | D38: =FS!E67/FS!E$72 -> 0.15726966 | E38: =FS!F67/FS!F$72 -> 0.12101663 | F38: =FS!G67/FS!G$72 -> 0.09325835 | G38: =FS!H67/FS!H$72 -> 0.17457338 | H38: =FS!I67/FS!I$72 -> 0.15333126 | I38: =FS!J67/FS!J$72 -> 0.27028939 | J38: =FS!K67/FS!K$72 -> 0.26661244 | ... L38: =FS!M67/FS!M$72 -> 0.2138266
B39: =FS!B68 -> Debtors | C39: =FS!D68/FS!D$72 -> 0.11240048 | D39: =FS!E68/FS!E$72 -> 0.11661248 | E39: =FS!F68/FS!F$72 -> 0.12574073 | F39: =FS!G68/FS!G$72 -> 0.11738253 | G39: =FS!H68/FS!H$72 -> 0.111242 | H39: =FS!I68/FS!I$72 -> 0.12783722 | I39: =FS!J68/FS!J$72 -> 0.16862826 | J39: =FS!K68/FS!K$72 -> 0.17987046 | ... L39: =FS!M68/FS!M$72 -> 0.14210557
B40: =FS!B69 -> Inventory | C40: =FS!D69/FS!D$72 -> 0.18924466 | D40: =FS!E69/FS!E$72 -> 0.21176137 | E40: =FS!F69/FS!F$72 -> 0.19314229 | F40: =FS!G69/FS!G$72 -> 0.19385138 | G40: =FS!H69/FS!H$72 -> 0.21005182 | H40: =FS!I69/FS!I$72 -> 0.18661442 | I40: =FS!J69/FS!J$72 -> 0.26800526 | J40: =FS!K69/FS!K$72 -> 0.24091549 | ... L40: =FS!M69/FS!M$72 -> 0.22135446
B41: =FS!B70 -> Total Current Assets (B) | C41: =FS!D70/FS!D$72 -> 0.3597035 | D41: =FS!E70/FS!E$72 -> 0.48564351 | E41: =FS!F70/FS!F$72 -> 0.43989965 | F41: =FS!G70/FS!G$72 -> 0.40449226 | G41: =FS!H70/FS!H$72 -> 0.4958672 | H41: =FS!I70/FS!I$72 -> 0.4677829 | I41: =FS!J70/FS!J$72 -> 0.7069229 | J41: =FS!K70/FS!K$72 -> 0.68739839 | ... L41: =FS!M70/FS!M$72 -> 0.57728663
B43: =FS!B72 -> Total Assets (A)+(B) | C43: =FS!D72/FS!D$72 -> 1 | D43: =FS!E72/FS!E$72 -> 1 | E43: =FS!F72/FS!F$72 -> 1 | F43: =FS!G72/FS!G$72 -> 1 | G43: =FS!H72/FS!H$72 -> 1 | H43: =FS!I72/FS!I$72 -> 1 | I43: =FS!J72/FS!J$72 -> 1 | J43: =FS!K72/FS!K$72 -> 1 | ... L43: =FS!M72/FS!M$72 -> 1

Sheet Intrinsic Growth
B2: ="Intrinsic Growth Calculation - "&'Profit & Loss'!$A$1 -> Intrinsic Growth Calculation - ASIAN PAINTS LTD
B5: ="ROIC Calculation - "&'Profit & Loss'!$A$1 -> ROIC Calculation - ASIAN PAINTS LTD | C5: ='Raw FS'!J3 -> 44256 | D5: ='Raw FS'!K3 -> 44621 | E5: ='Raw FS'!L3 -> 44986 | F5: ='Raw FS'!M3 -> 45352 | G5: ='Raw FS'!N3 -> 45717
B6: Current Assets -
B7: ='Raw FS'!B34 -> Inventories | C7: ='Raw FS'!J34 -> 3799 | D7: ='Raw FS'!K34 -> 6153 | E7: ='Raw FS'!L34 -> 6211 | F7: ='Raw FS'!M34 -> 5923 | G7: ='Raw FS'!N34 -> 6719
B8: ='Raw FS'!B35 -> Trade receivables + | C8: ='Raw FS'!J35 -> 2602 | D8: ='Raw FS'!K35 -> 3871 | E8: ='Raw FS'!L35 -> 4637 | F8: ='Raw FS'!M35 -> 4889 | G8: ='Raw FS'!N35 -> 4314
B9: ='Raw FS'!B37 -> Loans n Advances | C9: ='Raw FS'!J36 -> 611 | D9: ='Raw FS'!K36 -> 864 | E9: ='Raw FS'!L36 -> 844 | F9: ='Raw FS'!M36 -> 1084 | G9: ='Raw FS'!N36 -> 782
B10: ='Raw FS'!B38 -> Other asset items | C10: ='Raw FS'!J37 -> 11 | D10: ='Raw FS'!K37 -> 8 | E10: ='Raw FS'!L37 -> 12 | F10: ='Raw FS'!M37 -> 17 | G10: ='Raw FS'!N37 -> 22
B11: Total Current Assets | C11: =SUM(C7:C10) -> 7023 | D11: =SUM(D7:D10) -> 10896 | E11: =SUM(E7:E10) -> 11704 | F11: =SUM(F7:F10) -> 11913 | G11: =SUM(G7:G10) -> 11837
B13: Current Liabilities -
B14: ='Raw FS'!B13 -> Trade Payables | C14: ='Raw FS'!J13 -> 3379 | D14: ='Raw FS'!K13 -> 4164 | E14: ='Raw FS'!L13 -> 3635 | F14: ='Raw FS'!M13 -> 3831 | G14: ='Raw FS'!N13 -> 3848
B15: ='Raw FS'!B14 -> Advance from Customers | C15: ='Raw FS'!J14 -> 41 | D15: ='Raw FS'!K14 -> 76 | E15: ='Raw FS'!L14 -> 108 | F15: ='Raw FS'!M14 -> 154 | G15: ='Raw FS'!N14 -> 173
B16: ='Raw FS'!B15 -> Other liability items | C16: ='Raw FS'!J15 -> 2613 | D16: ='Raw FS'!K15 -> 2932 | E16: ='Raw FS'!L15 -> 3657 | F16: ='Raw FS'!M15 -> 4017 | G16: ='Raw FS'!N15 -> 3985
B17: Total Current Liabilities | C17: =SUM(C14:C16) -> 6033 | D17: =SUM(D14:D16) -> 7172 | E17: =SUM(E14:E16) -> 7400 | F17: =SUM(F14:F16) -> 8002 | G17: =SUM(G14:G16) -> 8006
B19: Net Working Capital | C19: =C11-C17 -> 990 | D19: =D11-D17 -> 3724 | E19: =E11-E17 -> 4304 | F19: =F11-F17 -> 3911 | G19: =G11-G17 -> 3831
B21: Non-Current Assets -
B22: ='Raw FS'!B19 -> Land | C22: ='Raw FS'!J19 -> 644 | D22: ='Raw FS'!K19 -> 644 | E22: ='Raw FS'!L19 -> 804 | F22: ='Raw FS'!M19 -> 1126 | G22: ='Raw FS'!N19 -> 1050
B23: ='Raw FS'!B20 -> Building | C23: ='Raw FS'!J20 -> 2249 | D23: ='Raw FS'!K20 -> 2325 | E23: ='Raw FS'!L20 -> 2883 | F23: ='Raw FS'!M20 -> 3390 | G23: ='Raw FS'!N20 -> 4136
B24: ='Raw FS'!B21 -> Plant Machinery | C24: ='Raw FS'!J21 -> 4340 | D24: ='Raw FS'!K21 -> 4531 | E24: ='Raw FS'!L21 -> 4825 | F24: ='Raw FS'!M21 -> 5422 | G24: ='Raw FS'!N21 -> 7576
B25: ='Raw FS'!B22 -> Equipments | C25: ='Raw FS'!J22 -> 243 | D25: ='Raw FS'!K22 -> 253 | E25: ='Raw FS'!L22 -> 270 | F25: ='Raw FS'!M22 -> 298 | G25: ='Raw FS'!N22 -> 325
B26: ='Raw FS'!B23 -> Furniture n fittings | C26: ='Raw FS'!J23 -> 99 | D26: ='Raw FS'!K23 -> 113 | E26: ='Raw FS'!L23 -> 146 | F26: ='Raw FS'!M23 -> 175 | G26: ='Raw FS'!N23 -> 203
B27: ='Raw FS'!B24 -> Vehicles | C27: ='Raw FS'!J24 -> 38 | D27: ='Raw FS'!K24 -> 32 | E27: ='Raw FS'!L24 -> 36 | F27: ='Raw FS'!M24 -> 40 | G27: ='Raw FS'!N24 -> 39
B28: ='Raw FS'!B25 -> Intangible Assets | C28: ='Raw FS'!J25 -> 476 | D28: ='Raw FS'!K25 -> 345 | E28: ='Raw FS'!L25 -> 422 | F28: ='Raw FS'!M25 -> 850 | G28: ='Raw FS'!N25 -> 827
B29: ='Raw FS'!B26 -> Other fixed assets | C29: ='Raw FS'!J26 -> 302 | D29: ='Raw FS'!K26 -> 294 | E29: ='Raw FS'!L26 -> 289 | F29: ='Raw FS'!M26 -> 321 | G29: ='Raw FS'!N26 -> 328
B30: ='Raw FS'!B27 -> Gross Block | C30: =SUM(C21:C29) -> 8391 | D30: =SUM(D21:D29) -> 8537 | E30: =SUM(E21:E29) -> 9675 | F30: =SUM(F21:F29) -> 11622 | G30: =SUM(G21:G29) -> 14484
B31: ='Raw FS'!B28 -> Accumulated Depreciation | C31: =-'Raw FS'!J28 -> -2533 | D31: =-'Raw FS'!K28 -> -3019 | E31: =-'Raw FS'!L28 -> -3905 | F31: =-'Raw FS'!M28 -> -4475 | G31: =-'Raw FS'!N28 -> -5264
B32: Net Assets | C32: =SUM(C30:C31) -> 5858 | D32: =SUM(D30:D31) -> 5518 | E32: =SUM(E30:E31) -> 5770 | F32: =SUM(F30:F31) -> 7147 | G32: =SUM(G30:G31) -> 9220
B34: Invested Capital | C34: =C32+C19 -> 6848 | D34: =D32+D19 -> 9242 | E34: =E32+E19 -> 10074 | F34: =F32+F19 -> 11058 | G34: =G32+G19 -> 13051
B35: EBIT | C35: =FS!D27 -> 2662.85 | D35: =FS!E27 -> 2996.87 | E35: =FS!F27 -> 3179.95 | F35: =FS!G27 -> 3416.57 | G35: =FS!H27 -> 3731.37
B37: ROIC | C37: =C35/C34 -> 0.38885076 | D37: =D35/D34 -> 0.32426639 | E37: =E35/E34 -> 0.31565912 | F37: =F35/F34 -> 0.30896817 | G37: =G35/G34 -> 0.28590683
B40: ="Reinvestment Rate Calculation - "&'Profit & Loss'!$A$1 -> Reinvestment Rate Calculation - ASIAN PAINTS LTD | C40: ='Raw FS'!J3 -> 44256 | D40: ='Raw FS'!K3 -> 44621 | E40: ='Raw FS'!L3 -> 44986 | F40: ='Raw FS'!M3 -> 45352 | G40: ='Raw FS'!N3 -> 45717
B42: Net Capex | C42: =-SUM('Raw FS'!J52:J53) -> 254 | D42: =-SUM('Raw FS'!K52:K53) -> 511 | E42: =-SUM('Raw FS'!L52:L53) -> 1420 | F42: =-SUM('Raw FS'!M52:M53) -> 2491 | G42: =-SUM('Raw FS'!N52:N53) -> 1820
B43: Change in Working Capital | D43: =D19-C19 -> 2734 | E43: =E19-D19 -> 580 | F43: =F19-E19 -> -393 | G43: =G19-F19 -> -80
B45: EBIT | C45: =FS!D27 -> 2662.85 | D45: =FS!E27 -> 2996.87 | E45: =FS!F27 -> 3179.95 | F45: =FS!G27 -> 3416.57 | G45: =FS!H27 -> 3731.37
B46: Marginal Tax Rate | C46: 0.3 | D46: =C46 -> 0.3 | E46: =D46 -> 0.3 | F46: =E46 -> 0.3 | G46: =F46 -> 0.3
B47: EBIT*(1-T) | C47: =C45*(1-C46) -> 1863.995 | D47: =D45*(1-D46) -> 2097.809 | E47: =E45*(1-E46) -> 2225.965 | F47: =F45*(1-F46) -> 2391.599 | G47: =G45*(1-G46) -> 2611.959
B49: Reinvestment | D49: =SUM(D42:D43) -> 3245 | E49: =SUM(E42:E43) -> 2000 | F49: =SUM(F42:F43) -> 2098 | G49: =SUM(G42:G43) -> 1740
B50: Reinvestment Rate | D50: =D49/D47 -> 1.546852 | E50: =E49/E47 -> 0.89848672 | F50: =F49/F47 -> 0.87723736 | G50: =G49/G47 -> 0.66616666
E51: 4 Year Average | G51: =AVERAGE(D50:G50) -> 0.99718568
E52: 4 Year Median | G52: =MEDIAN(D50:G50) -> 0.88786204
B54: ="Intrinsic Growth Calculation - "&'Profit & Loss'!$A$1 -> Intrinsic Growth Calculation - ASIAN PAINTS LTD | D54: ='Raw FS'!K3 -> 44621 | E54: ='Raw FS'!L3 -> 44986 | F54: ='Raw FS'!M3 -> 45352 | G54: ='Raw FS'!N3 -> 45717
...

Sheet Raw FS
C3: 41699 | D3: 42064 | E3: 42430 | F3: 42795 | G3: 43160 | H3: 43525 | I3: 43891 | J3: 44256 | K3: 44621 | L3: 44986 | M3: 45352 | N3: 45717
B4: Equity Capital | C4: 96 | D4: 96 | E4: 96 | F4: 96 | G4: 96 | H4: 96 | I4: 96 | J4: 96 | K4: 96 | L4: 96 | M4: 96 | N4: 96
B5: Reserves | C5: 3943 | D5: 4646 | E5: 6429 | F5: 7508 | G5: 8314 | H5: 9375 | I5: 10034 | J5: 12710 | K5: 13716 | L5: 15896 | M5: 18632 | N5: 19304
B6: Borrowings -
B7: Long term Borrowings | C7: 41 | D7: 78 | E7: 73 | F7: 41 | G7: 28 | H7: 19 | I7: 19 | J7: 15 | K7: 45 | L7: 76 | M7: 54 | N7: 260
B8: Short term Borrowings | C8: 199 | D8: 332 | E8: 231 | F8: 504 | G8: 492 | H8: 597 | I8: 321 | J8: 334 | K8: 731 | L8: 896 | M8: 1053 | N8: 604
B9: Lease Liabilities | C9: 0 | D9: 0 | E9: 0 | F9: 0 | G9: 0 | H9: 693 | I9: 764 | J9: 745 | K9: 811 | L9: 960 | M9: 1367 | N9: 1427
B10: Other Borrowings | C10: 9 | D10: 8 | E10: 20 | F10: 15 | G10: 13 | H10: 11 | I10: 15 | J10: 0 | K10: 0 | L10: 0 | M10: 0 | N10: 0
B11: Other Liabilities -
B12: Non controlling int | C12: 246 | D12: 264 | E12: 384 | F12: 375 | G12: 328 | H12: 361 | I12: 404 | J12: 423 | K12: 388 | L12: 454 | M12: 695 | N12: 659
B13: Trade Payables | C13: 1746 | D13: 1549 | E13: 1565 | F13: 1923 | G13: 2160 | H13: 2394 | I13: 2137 | J13: 3379 | K13: 4164 | L13: 3635 | M13: 3831 | N13: 3848
B14: Advance from Customers | C14: 0 | D14: 5 | E14: 12 | F14: 17 | G14: 16 | H14: 13 | I14: 29 | J14: 41 | K14: 76 | L14: 108 | M14: 154 | N14: 173
B15: Other liability items | C15: 1795 | D15: 1937 | E15: 1750 | F15: 1925 | G15: 2316 | H15: 2690 | I15: 2320 | J15: 2613 | K15: 2932 | L15: 3657 | M15: 4017 | N15: 3985
B16: Total Liabilities | C16: 8075 | D16: 8914 | E16: 10559 | F16: 12405 | G16: 13763 | H16: 16249 | I16: 16138 | J16: 20355 | K16: 22958 | L16: 25779 | M16: 29901 | N16: 30355
B18: Fixed Assets -
B19: Land | C19: 247 | D19: 251 | E19: 429 | F19: 408 | G19: 586 | H19: 605 | I19: 640 | J19: 644 | K19: 644 | L19: 804 | M19: 1126 | N19: 1050
B20: Building | C20: 931 | D20: 962 | E20: 923 | F20: 931 | G20: 957 | H20: 2402 | I20: 2257 | J20: 2249 | K20: 2325 | L20: 2883 | M20: 3390 | N20: 4136
B21: Plant Machinery | C21: 2054 | D21: 2132 | E21: 1793 | F21: 1980 | G21: 2157 | H21: 4006 | I21: 4208 | J21: 4340 | K21: 4531 | L21: 4825 | M21: 5422 | N21: 7576
B22: Equipments | C22: 155 | D22: 171 | E22: 97 | F22: 119 | G22: 200 | H22: 221 | I22: 241 | J22: 243 | K22: 253 | L22: 270 | M22: 298 | N22: 325
B23: Furniture n fittings | C23: 71 | D23: 83 | E23: 49 | F23: 59 | G23: 72 | H23: 88 | I23: 94 | J23: 99 | K23: 113 | L23: 146 | M23: 175 | N23: 203
B24: Vehicles | C24: 14 | D24: 18 | E24: 11 | F24: 14 | G24: 27 | H24: 47 | I24: 43 | J24: 38 | K24: 32 | L24: 36 | M24: 40 | N24: 39
B25: Intangible Assets | C25: 203 | D25: 351 | E25: 339 | F25: 276 | G25: 468 | H25: 512 | I25: 505 | J25: 476 | K25: 345 | L25: 422 | M25: 850 | N25: 827
B26: Other fixed assets | C26: 128 | D26: 145 | E26: 103 | F26: 128 | G26: 238 | H26: 261 | I26: 293 | J26: 302 | K26: 294 | L26: 289 | M26: 321 | N26: 328
B27: Gross Block | C27: 3804 | D27: 4112 | E27: 3744 | F27: 3914 | G27: 4705 | H27: 8141 | I27: 8282 | J27: 8392 | K27: 8538 | L27: 9676 | M27: 11622 | N27: 14484
B28: Accumulated Depreciation | C28: 1242 | D28: 1452 | E28: 327 | F28: 610 | G28: 973 | H28: 1644 | I28: 2010 | J28: 2533 | K28: 3019 | L28: 3905 | M28: 4475 | N28: 5264
B29: Net Block | C29: =C27-C28 -> 2562 | D29: =D27-D28 -> 2660 | E29: =E27-E28 -> 3417 | F29: =F27-F28 -> 3304 | G29: =G27-G28 -> 3732 | H29: =H27-H28 -> 6497 | I29: =I27-I28 -> 6272 | J29: =J27-J28 -> 5859 | ... N29: =N27-N28 -> 9220
B31: CWIP | C31: 72 | D31: 196 | E31: 107 | F31: 258 | G31: 1405 | H31: 210 | I31: 140 | J31: 183 | K31: 426 | L31: 1020 | M31: 2698 | N31: 1254
B32: Investments | C32: 1424 | D32: 1588 | E32: 2712 | F32: 2652 | G32: 2141 | H32: 2569 | I32: 2019 | J32: 4737 | K32: 3248 | L32: 4262 | M32: 4588 | N32: 4725
B33: Other Assets -
B34: Inventories | C34: 2070 | D34: 2259 | E34: 1998 | F34: 2627 | G34: 2658 | H34: 3150 | I34: 3390 | J34: 3799 | K34: 6153 | L34: 6211 | M34: 5923 | N34: 6719
B35: Trade receivables + | C35: 1110 | D35: 1182 | E35: 1187 | F35: 1447 | G35: 1731 | H35: 1907 | I35: 1795 | J35: 2602 | K35: 3871 | L35: 4637 | M35: 4889 | N35: 4314
B36: Cash Equivalents | C36: 229 | D36: 204 | E36: 424 | F36: 801 | G36: 405 | H36: 445 | I36: 783 | J36: 611 | K36: 864 | L36: 844 | M36: 1084 | N36: 782
B37: Loans n Advances | C37: 7 | D37: 8 | E37: 9 | F37: 14 | G37: 13 | H37: 16 | I37: 12 | J37: 11 | K37: 8 | L37: 12 | M37: 17 | N37: 22
B38: Other asset items | C38: 603 | D38: 817 | E38: 705 | F38: 1303 | G38: 1678 | H38: 1456 | I38: 1727 | J38: 2555 | K38: 2869 | L38: 3024 | M38: 3555 | N38: 3319
B39: Total Assets | C39: 8075 | D39: 8914 | E39: 10559 | F39: 12405 | G39: 13763 | H39: 16249 | I39: 16138 | J39: 20355 | K39: 22958 | L39: 25779 | M39: 29901 | N39: 30355
C42: Cashflow Statement
B43: Cash from Operating Activity - | C43: 1402 | D43: 1188 | E43: 2243 | F43: 1527 | G43: 2113 | H43: 2470 | I43: 3038 | J43: 3683 | K43: 986 | L43: 4193 | M43: 6104 | N43: 4424
B44: Profit from operations | C44: 2051 | D44: 2271 | E44: 2848 | F44: 3056 | G44: 3274 | H44: 3861 | I44: 4380 | J44: 4970 | K44: 4957 | L44: 6460 | M44: 7929 | N44: 6390
B45: Receivables | C45: -254 | D45: -155 | E45: -146 | F45: -475 | G45: -483 | H45: -205 | I45: 160 | J45: -849 | K45: -1326 | L45: -834 | M45: -362 | N45: 282
B46: Inventory | C46: -231 | D46: -144 | E46: 202 | F46: -629 | G46: -39 | H46: -492 | I46: -251 | J46: -409 | K46: -2354 | L46: -56 | M46: 315 | N46: -805
...

Sheet Data
B2: S.No. | C2: Name | D2: CMP Rs. | E2: No. Eq. Shares Cr. | F2: Mar Cap Rs.Cr. | G2: Debt Rs.Cr. | H2: Cash End Rs.Cr. | I2: EV Rs.Cr. | J2: Sales Rs.Cr. | K2: EBITDA | L2: EV / EBITDA | M2: NP 12M Rs.Cr.
B3: 1 | C3: Asian Paints | D3: 2536.1 | E3: 95.92 | F3: 243262.14 | G3: 2290.29 | H3: 781.98 | I3: 244770.45 | J3: 33874.44 | K3: =I3/L3 -> 6687.7172 | L3: 36.6 | M3: 3639.97
B4: 2 | C4: Berger Paints | D4: 532.5 | E4: 116.59 | F4: 62083.93 | G4: 670.27 | H4: 500.48 | I4: 62253.72 | J4: 11654.46 | K4: =I4/L4 -> 1985.7646 | L4: 31.35 | M4: 1143.82
B5: 3 | C5: Kansai Nerolac | D5: 245.85 | E5: 80.85 | F5: 19877.04 | G5: 296.39 | H5: 290.06 | I5: 19883.37 | J5: 7851.94 | K5: =I5/L5 -> 1073.6161 | L5: 18.52 | M5: 1100.05
B6: 4 | C6: Akzo Nobel | D6: 3389.75 | E6: 4.55 | F6: 15437.03 | G6: 62.1 | H6: 299.5 | I6: 15199.63 | J6: 4050 | K6: =I6/L6 -> 633.58191 | L6: 23.99 | M6: 405
B7: 5 | C7: Indigo Paints | D7: 1130 | E7: 4.76 | F7: 5382.74 | G7: 19.7 | H7: 37.1 | I7: 5365.34 | J7: 1278.1 | K7: =I7/L7 -> 248.51042 | L7: 21.59 | M7: 143.84
B8: 6 | C8: Sirca Paints | D8: 461.75 | E8: 5.48 | F8: 2530.82 | G8: 8.33 | H8: 54.2 | I8: 2484.95 | J8: 409.37 | K8: =I8/L8 -> 79.901929 | L8: 31.1 | M8: 53.05
B9: 7 | C9: Shalimar Paints | D9: 74 | E9: 8.37 | F9: 619.5 | G9: 163.86 | H9: 45.47 | I9: 737.89 | J9: 624.19 | K9: =I9/L9 -> -32.520494 | L9: -22.69 | M9: -69.79
B10: 8 | C10: Kamdhenu Venture | D10: 9.06 | E10: 31.44 | F10: 284.81 | G10: 26.98 | H10: 5.9 | I10: 305.89 | J10: 261.89 | K10: =I10/L10 -> 16.770285 | L10: 18.24 | M10: 5.94
B11: 9 | C11: Siddhika Coatins | D11: 200.5 | E11: 0.62 | F11: 123.89 | G11: 0 | H11: 5.76 | I11: 118.13 | J11: 48.01 | K11: =I11/L11 -> 10.435512 | L11: 11.32 | M11: 8.03
B12: 10 | C12: Retina Paints | D12: 73 | E12: 1.53 | F12: 111.99 | G12: 8.12 | H12: 0.36 | I12: 119.78 | J12: 11.66 | K12: =I12/L12 -> 2.0198988 | L12: 59.3 | M12: 0.74

Sheet WACC
B2: WACC
B5: Weighted Average Cost of Capital
B7: All figures in inr crores unless stated otherwise
B9: Peer Comps
J10: Debt/ | K10: Debt/
B11: Name of the company | F11: Country | G11: Total Debt | H11: Total Equity | I11: Tax Rate 1 | J11: Equity | K11: Capital | L11: Levered Beta 2 | M11: Unlevered Beta 3
B12: Asian Paints | F12: India | G12: 2290 | H12: 244873.61 | I12: 0.3 | J12: =G12/H12 -> 0.0093517631 | K12: =G12/(G12+H12) -> 0.009265118 | L12: =Beta!AF8 -> 0.81569883 | M12: =L12/(1+(1-I12)*J12) -> 0.8103938
B13: Berger Paints | F13: India | G13: 670 | H13: 63692.79 | I13: 0.3 | J13: =G13/H13 -> 0.010519244 | K13: =G13/(G13+H13) -> 0.010409741 | L13: =Beta!AF9 -> 0.84864224 | M13: =L13/(1+(1-I13)*J13) -> 0.84243896
B14: Indigo Paints | F14: India | G14: 27.3 | H14: 5425.61 | I14: 0.3 | J14: =G14/H14 -> 0.0050316923 | K14: =G14/(G14+H14) -> 0.0050065011 | L14: =Beta!AF10 -> 0.72419311 | M14: =L14/(1+(1-I14)*J14) -> 0.72165132
B15: Sirca Paints | F15: India | G15: 50 | H15: 2516.81 | I15: 0.3 | J15: =G15/H15 -> 0.019866418 | K15: =G15/(G15+H15) -> 0.019479432 | L15: =Beta!AF11 -> 0.90098808 | M15: =L15/(1+(1-I15)*J15) -> 0.88863035
B16: Shalimar Paints | F16: India | G16: 164 | H16: 616.99 | I16: 0.3 | J16: =G16/H16 -> 0.26580658 | K16: =G16/(G16+H16) -> 0.20998988 | L16: =Beta!AF12 -> 0.69537713 | M16: =L16/(1+(1-I16)*J16) -> 0.58628942
B17: Kansai Nerolac Paints | F17: India | G17: 296 | H17: 20042.86 | I17: 0.3 | J17: =G17/H17 -> 0.014768351 | K17: =G17/(G17+H17) -> 0.014553421 | L17: =Beta!AF13 -> 0.80537586 | M17: =L17/(1+(1-I17)*J17) -> 0.7971352
H19: Average | I19: =AVERAGE(I13:I17) -> 0.3 | J19: =AVERAGE(J13:J17) -> 0.063198457 | K19: =AVERAGE(K13:K17) -> 0.051887796 | L19: =AVERAGE(L13:L17) -> 0.79491528 | M19: =AVERAGE(M13:M17) -> 0.76722905
H20: Median | I20: =MEDIAN(I13:I17) -> 0.3 | J20: =MEDIAN(J13:J17) -> 0.014768351 | K20: =MEDIAN(K13:K17) -> 0.014553421 | L20: =MEDIAN(L13:L17) -> 0.80537586 | M20: =MEDIAN(M13:M17) -> 0.7971352
B22: Cost of Debt | I22: Cost of Equity
B24: Pre Tax Cost of Debt | G24: =216/G12 -> 0.094323144 | I24: Risk Free Rate | M24: 0.0649
B25: Tax Rate | G25: 0.3 | I25: Equity Risk Premium | M25: ='Market Returns'!G8-WACC!M24 -> 0.088448
B26: Post Tax Cost of Debt | G26: =G24*(1-G25) -> 0.066026201 | I26: Levered Beta 4 | M26: =Beta!AF15 -> 0.80537586
I27: Total Equity | M27: =(M24+M25)*M26 -> 0.12350278
B29: Total Capital | I29: Levered Beta
F31: Current | G31: Target | I31: Peer Comps Unlevered Beta Median | M31: =M20 -> 0.7971352
B32: Total Debt | E32: =G13 -> 670 | F32: =E32/$E$34 -> 0.010409741 | G32: =K19 -> 0.051887796 | I32: Target D/E | M32: =G36 -> 0.054727485
B33: Total Equity | E33: =H13 -> 63692.79 | F33: =E33/$E$34 -> 0.98959026 | G33: =G34-G32 -> 0.9481122 | I33: Tax Rate | M33: =G25 -> 0.3
B34: Total Capital | E34: =SUM(E32:E33) -> 64362.79 | F34: =SUM(F32:F33) -> 1 | G34: =F34 -> 1 | I34: Levered Beta | M34: =M31*(1+(1-M32)*M33) -> 1.0231882
B36: Debt/Equity | F36: =F32/F33 -> 0.010519244 | G36: =G32/G33 -> 0.054727485 | I36: Weighted Avg. Cost of Capital
I38: Cost of Debt | M38: =G26 -> 0.066026201
I39: Weight of Debt | M39: =G32 -> 0.051887796
B40: Notes:
B41: 1. Tax Rate is marginal tax rate for the country | I41: Cost of Equity | M41: =M27 -> 0.12350278
B42: 2. Levered Beta = Unlevered beta/(1+(1 - Tax rate)* Debt/Equity | I42: Weight of Equity | M42: =G33 -> 0.9481122
B43: 3. Unlevered Beta = Levered beta*(1+(1 - Tax rate)* Debt/Equity | I43: WACC | M43: =(M38*M39)+(M41*M42) -> 0.12052044

Sheet WACC Data->

Sheet Beta
B2: ="Beta Regression "&'Profit & Loss'!A1&" & Peer Comps" -> Beta Regression ASIAN PAINTS LTD & Peer Comps
B5: ='Profit & Loss'!A1 &" 2 Year Weekly Returns" -> ASIAN PAINTS LTD 2 Year Weekly Returns | F5: Berger Paints 2 Year Weekly Returns | J5: Indigo Paints 2 Year Weekly Returns | N5: Sirca Paints 2 Year Weekly Returns | R5: Shalimar Paints 2 Year Weekly Returns | V5: Kansai Nerolac 2 Year Weekly Returns | Z5: Nifty 2 Year Weekly Returns | AD5: Beta of companies with respect to Nifty
B7: Date | C7: Closing Price | D7: Returns | F7: Date | G7: Closing Price | H7: Returns | J7: Date | K7: Closing Price | L7: Returns | N7: Date | O7: Closing Price | P7: Returns | R7: Date | S7: Closing Price | T7: Returns | V7: Date | W7: Closing Price | X7: Returns | Z7: Date | AA7: Closing Price | AB7: Returns | AD7: Companies | AF7: Beta
B8: 45179 | C8: 3196.65 | F8: 45179 | G8: 599.71 | J8: 45179 | K8: 1535.15 | N8: 45179 | O8: 400.5 | R8: 45179 | S8: 157.9 | V8: 45179 | W8: 325.21 | Z8: 45179 | AA8: 20192.35 | AD8: Asian Paints | AF8: =SLOPE(D$9:D$111,$AB$9:$AB$111) -> 0.81569883
B9: =B8+7 -> 45186 | C9: 3274.85 | D9: =C9/C8-1 -> 0.02446311 | F9: =F8+7 -> 45186 | G9: 667.8 | H9: =G9/G8-1 -> 0.11353821 | J9: =J8+7 -> 45186 | K9: 1549.15 | L9: =K9/K8-1 -> 0.00911963 | N9: =N8+7 -> 45186 | O9: 390.1 | P9: =O9/O8-1 -> -0.025967541 | R9: =R8+7 -> 45186 | S9: 153.25 | T9: =S9/S8-1 -> -0.029449018 | V9: =V8+7 -> 45186 | W9: 321.03 | X9: =W9/W8-1 -> -0.012853233 | Z9: =Z8+7 -> 45186 | AA9: 19674.25 | AB9: =AA9/AA8-1 -> -0.025658232 | AD9: =WACC!B13 -> Berger Paints | AF9: =SLOPE(H$9:H$111,$AB$9:$AB$111) -> 0.84864224
B10: =B9+7 -> 45193 | C10: 3161.05 | D10: =C10/C9-1 -> -0.034749683 | F10: =F9+7 -> 45193 | G10: 568.9 | H10: =G10/G9-1 -> -0.14809823 | J10: =J9+7 -> 45193 | K10: 1485.8 | L10: =K10/K9-1 -> -0.040893393 | N10: =N9+7 -> 45193 | O10: 388.65 | P10: =O10/O9-1 -> -0.0037169956 | R10: =R9+7 -> 45193 | S10: 161.3 | T10: =S10/S9-1 -> 0.052528548 | V10: =V9+7 -> 45193 | W10: 316.05 | X10: =W10/W9-1 -> -0.015512569 | Z10: =Z9+7 -> 45193 | AA10: 19638.3 | AB10: =AA10/AA9-1 -> -0.0018272615 | AD10: =WACC!B14 -> Indigo Paints | AF10: =SLOPE(L$9:L$111,$AB$9:$AB$111) -> 0.72419311
B11: =B10+7 -> 45200 | C11: 3195.75 | D11: =C11/C10-1 -> 0.010977365 | F11: =F10+7 -> 45200 | G11: 565.2 | H11: =G11/G10-1 -> -0.0065037792 | J11: =J10+7 -> 45200 | K11: 1506.45 | L11: =K11/K10-1 -> 0.013898237 | N11: =N10+7 -> 45200 | O11: 387.3 | P11: =O11/O10-1 -> -0.0034735623 | R11: =R10+7 -> 45200 | S11: 164 | T11: =S11/S10-1 -> 0.016738996 | V11: =V10+7 -> 45200 | W11: 322.37 | X11: =W11/W10-1 -> 0.019996836 | Z11: =Z10+7 -> 45200 | AA11: 19653.5 | AB11: =AA11/AA10-1 -> 0.00077399775 | AD11: =WACC!B15 -> Sirca Paints | AF11: =SLOPE(P$9:P$111,$AB$9:$AB$111) -> 0.90098808
B12: =B11+7 -> 45207 | C12: 3148.8 | D12: =C12/C11-1 -> -0.014691387 | F12: =F11+7 -> 45207 | G12: 568.1 | H12: =G12/G11-1 -> 0.0051309271 | J12: =J11+7 -> 45207 | K12: 1455.4 | L12: =K12/K11-1 -> -0.033887617 | N12: =N11+7 -> 45207 | O12: 386.65 | P12: =O12/O11-1 -> -0.0016782856 | R12: =R11+7 -> 45207 | S12: 192.45 | T12: =S12/S11-1 -> 0.17347561 | V12: =V11+7 -> 45207 | W12: 321.47 | X12: =W12/W11-1 -> -0.0027918231 | Z12: =Z11+7 -> 45207 | AA12: 19751.05 | AB12: =AA12/AA11-1 -> 0.0049634925 | AD12: =WACC!B16 -> Shalimar Paints | AF12: =SLOPE(T$9:T$111,$AB$9:$AB$111) -> 0.69537713
B13: =B12+7 -> 45214 | C13: 3105.85 | D13: =C13/C12-1 -> -0.013640117 | F13: =F12+7 -> 45214 | G13: 584.2 | H13: =G13/G12-1 -> 0.028340081 | J13: =J12+7 -> 45214 | K13: 1458.6 | L13: =K13/K12-1 -> 0.0021987083 | N13: =N12+7 -> 45214 | O13: 371.15 | P13: =O13/O12-1 -> -0.040087935 | R13: =R12+7 -> 45214 | S13: 186.15 | T13: =S13/S12-1 -> -0.032735776 | V13: =V12+7 -> 45214 | W13: 319.83 | X13: =W13/W12-1 -> -0.0051015647 | Z13: =Z12+7 -> 45214 | AA13: 19542.65 | AB13: =AA13/AA12-1 -> -0.010551338 | AD13: =WACC!B17 -> Kansai Nerolac Paints | AF13: =SLOPE(X$9:X$111,$AB$9:$AB$111) -> 0.80537586
B14: =B13+7 -> 45221 | C14: 2955.15 | D14: =C14/C13-1 -> -0.048521339 | F14: =F13+7 -> 45221 | G14: 535.35 | H14: =G14/G13-1 -> -0.083618624 | J14: =J13+7 -> 45221 | K14: 1411.8 | L14: =K14/K13-1 -> -0.032085561 | N14: =N13+7 -> 45221 | O14: 368.3 | P14: =O14/O13-1 -> -0.0076788361 | R14: =R13+7 -> 45221 | S14: 184.75 | T14: =S14/S13-1 -> -0.0075208165 | V14: =V13+7 -> 45221 | W14: 312.17 | X14: =W14/W13-1 -> -0.023950224 | Z14: =Z13+7 -> 45221 | AA14: 19047.25 | AB14: =AA14/AA13-1 -> -0.025349684
B15: =B14+7 -> 45228 | C15: 2977.85 | D15: =C15/C14-1 -> 0.0076815052 | F15: =F14+7 -> 45228 | G15: 553.25 | H15: =G15/G14-1 -> 0.03343607 | J15: =J14+7 -> 45228 | K15: 1464.1 | L15: =K15/K14-1 -> 0.037044907 | N15: =N14+7 -> 45228 | O15: 369 | P15: =O15/O14-1 -> 0.0019006245 | R15: =R14+7 -> 45228 | S15: 180.45 | T15: =S15/S14-1 -> -0.023274696 | V15: =V14+7 -> 45228 | W15: 303.65 | X15: =W15/W14-1 -> -0.027292821 | Z15: =Z14+7 -> 45228 | AA15: 19230.6 | AB15: =AA15/AA14-1 -> 0.0096260615 | AD15: Peer Comps Beta Median | AF15: =MEDIAN(AF9:AF13) -> 0.80537586
B16: =B15+7 -> 45235 | C16: 3076.45 | D16: =C16/C15-1 -> 0.033111137 | F16: =F15+7 -> 45235 | G16: 578.25 | H16: =G16/G15-1 -> 0.045187528 | J16: =J15+7 -> 45235 | K16: 1502.95 | L16: =K16/K15-1 -> 0.026535073 | N16: =N15+7 -> 45235 | O16: 375.55 | P16: =O16/O15-1 -> 0.017750678 | R16: =R15+7 -> 45235 | S16: 173.4 | T16: =S16/S15-1 -> -0.039068994 | V16: =V15+7 -> 45235 | W16: 303.05 | X16: =W16/W15-1 -> -0.0019759592 | Z16: =Z15+7 -> 45235 | AA16: 19425.35 | AB16: =AA16/AA15-1 -> 0.010127089
B17: =B16+7 -> 45242 | C17: 3168.9 | D17: =C17/C16-1 -> 0.03005087 | F17: =F16+7 -> 45242 | G17: 587.8 | H17: =G17/G16-1 -> 0.016515348 | J17: =J16+7 -> 45242 | K17: 1539.65 | L17: =K17/K16-1 -> 0.024418643 | N17: =N16+7 -> 45242 | O17: 380.8 | P17: =O17/O16-1 -> 0.013979497 | R17: =R16+7 -> 45242 | S17: 178.65 | T17: =S17/S16-1 -> 0.030276817 | V17: =V16+7 -> 45242 | W17: 323.96 | X17: =W17/W16-1 -> 0.068998515 | Z17: =Z16+7 -> 45242 | AA17: 19731.8 | AB17: =AA17/AA16-1 -> 0.015775778
B18: =B17+7 -> 45249 | C18: 3136.15 | D18: =C18/C17-1 -> -0.010334816 | F18: =F17+7 -> 45249 | G18: 573.2 | H18: =G18/G17-1 -> -0.02483838 | J18: =J17+7 -> 45249 | K18: 1482.5 | L18: =K18/K17-1 -> -0.037118826 | N18: =N17+7 -> 45249 | O18: 370.1 | P18: =O18/O17-1 -> -0.028098739 | R18: =R17+7 -> 45249 | S18: 170.25 | T18: =S18/S17-1 -> -0.047019312 | V18: =V17+7 -> 45249 | W18: 318.93 | X18: =W18/W17-1 -> -0.015526608 | Z18: =Z17+7 -> 45249 | AA18: 19794.7 | AB18: =AA18/AA17-1 -> 0.0031877477 | AD18: Beta Drifting
B19: =B18+7 -> 45256 | C19: 3173.4 | D19: =C19/C18-1 -> 0.011877621 | F19: =F18+7 -> 45256 | G19: 586.05 | H19: =G19/G18-1 -> 0.022418004 | J19: =J18+7 -> 45256 | K19: 1497.75 | L19: =K19/K18-1 -> 0.010286678 | N19: =N18+7 -> 45256 | O19: 382.65 | P19: =O19/O18-1 -> 0.033909754 | R19: =R18+7 -> 45256 | S19: 198.7 | T19: =S19/S18-1 -> 0.1671072 | V19: =V18+7 -> 45256 | W19: 318.64 | X19: =W19/W18-1 -> -0.00090929044 | Z19: =Z18+7 -> 45256 | AA19: 20267.9 | AB19: =AA19/AA18-1 -> 0.023905389 | AD19: Levered Raw Beta | AF19: =AF8 -> 0.81569883
B20: =B19+7 -> 45263 | C20: 3232 | D20: =C20/C19-1 -> 0.018465999 | F20: =F19+7 -> 45263 | G20: 578.75 | H20: =G20/G19-1 -> -0.012456275 | J20: =J19+7 -> 45263 | K20: 1489 | L20: =K20/K19-1 -> -0.0058420965 | N20: =N19+7 -> 45263 | O20: 392.2 | P20: =O20/O19-1 -> 0.024957533 | R20: =R19+7 -> 45263 | S20: 181.8 | T20: =S20/S19-1 -> -0.085052843 | V20: =V19+7 -> 45263 | W20: 328.89 | X20: =W20/W19-1 -> 0.032167964 | Z20: =Z19+7 -> 45263 | AA20: 20969.4 | AB20: =AA20/AA19-1 -> 0.034611381 | AD20: Beta Weight | AF20: 0.75
B21: =B20+7 -> 45270 | C21: 3313.9 | D21: =C21/C20-1 -> 0.025340347 | F21: =F20+7 -> 45270 | G21: 585.35 | H21: =G21/G20-1 -> 0.011403888 | J21: =J20+7 -> 45270 | K21: 1478.9 | L21: =K21/K20-1 -> -0.0067830759 | N21: =N20+7 -> 45270 | O21: 390.4 | P21: =O21/O20-1 -> -0.0045894952 | R21: =R20+7 -> 45270 | S21: 181.9 | T21: =S21/S20-1 -> 0.00055005501 | V21: =V20+7 -> 45270 | W21: 331.43 | X21: =W21/W20-1 -> 0.0077229469 | Z21: =Z20+7 -> 45270 | AA21: 21456.65 | AB21: =AA21/AA20-1 -> 0.023236239
B22: =B21+7 -> 45277 | C22: 3341.3 | D22: =C22/C21-1 -> 0.0082682036 | F22: =F21+7 -> 45277 | G22: 582.55 | H22: =G22/G21-1 -> -0.0047834629 | J22: =J21+7 -> 45277 | K22: 1465.6 | L22: =K22/K21-1 -> -0.0089931706 | N22: =N21+7 -> 45277 | O22: 399.35 | P22: =O22/O21-1 -> 0.022925205 | R22: =R21+7 -> 45277 | S22: 181.4 | T22: =S22/S21-1 -> -0.0027487631 | V22: =V21+7 -> 45277 | W22: 321.03 | X22: =W22/W21-1 -> -0.031379175 | Z22: =Z21+7 -> 45277 | AA22: 21349.4 | AB22: =AA22/AA21-1 -> -0.0049984504 | AD22: Market Beta | AF22: 1
B23: =B22+7 -> 45284 | C23: 3402.4 | D23: =C23/C22-1 -> 0.018286296 | F23: =F22+7 -> 45284 | G23: 604.45 | H23: =G23/G22-1 -> 0.03759334 | J23: =J22+7 -> 45284 | K23: 1490.5 | L23: =K23/K22-1 -> 0.016989629 | N23: =N22+7 -> 45284 | O23: 409.85 | P23: =O23/O22-1 -> 0.026292726 | R23: =R22+7 -> 45284 | S23: 177.7 | T23: =S23/S22-1 -> -0.020396913 | V23: =V22+7 -> 45284 | W23: 331.78 | X23: =W23/W22-1 -> 0.033485967 | Z23: =Z22+7 -> 45284 | AA23: 21731.4 | AB23: =AA23/AA22-1 -> 0.017892775 | AD23: Market Beta Weight | AF23: =1-AF20 -> 0.25
B24: =B23+7 -> 45291 | C24: 3355.55 | D24: =C24/C23-1 -> -0.013769692 | F24: =F23+7 -> 45291 | G24: 595.9 | H24: =G24/G23-1 -> -0.014145091 | J24: =J23+7 -> 45291 | K24: 1498.75 | L24: =K24/K23-1 -> 0.0055350554 | N24: =N23+7 -> 45291 | O24: 427.8 | P24: =O24/O23-1 -> 0.043796511 | R24: =R23+7 -> 45291 | S24: 184.2 | T24: =S24/S23-1 -> 0.036578503 | V24: =V23+7 -> 45291 | W24: 335.21 | X24: =W24/W23-1 -> 0.010338176 | Z24: =Z23+7 -> 45291 | AA24: 21710.8 | AB24: =AA24/AA23-1 -> -0.00094793709
B25: =B24+7 -> 45298 | C25: 3277.8 | D25: =C25/C24-1 -> -0.023170568 | F25: =F24+7 -> 45298 | G25: 596.1 | H25: =G25/G24-1 -> 0.00033562678 | J25: =J24+7 -> 45298 | K25: 1484.55 | L25: =K25/K24-1 -> -0.0094745621 | N25: =N24+7 -> 45298 | O25: 424.9 | P25: =O25/O24-1 -> -0.0067788686 | R25: =R24+7 -> 45298 | S25: 180.55 | T25: =S25/S24-1 -> -0.019815418 | V25: =V24+7 -> 45298 | W25: 338.8 | X25: =W25/W24-1 -> 0.010709704 | Z25: =Z24+7 -> 45298 | AA25: 21894.55 | AB25: =AA25/AA24-1 -> 0.0084635297 | AD25: Adjusted Beta | AF25: =(AF19*AF20)+(AF22*AF23) -> 0.86177412
B26: =B25+7 -> 45305 | C26: 3165.85 | D26: =C26/C25-1 -> -0.034154006 | F26: =F25+7 -> 45305 | G26: 579.55 | H26: =G26/G25-1 -> -0.027763798 | J26: =J25+7 -> 45305 | K26: 1469.25 | L26: =K26/K25-1 -> -0.010306153 | N26: =N25+7 -> 45305 | O26: 409 | P26: =O26/O25-1 -> -0.03742057 | R26: =R25+7 -> 45305 | S26: 217.75 | T26: =S26/S25-1 -> 0.20603711 | V26: =V25+7 -> 45305 | W26: 342.78 | X26: =W26/W25-1 -> 0.011747344 | Z26: =Z25+7 -> 45305 | AA26: 21622.4 | AB26: =AA26/AA25-1 -> -0.012430034
B27: =B26+7 -> 45312 | C27: 2949.2 | D27: =C27/C26-1 -> -0.068433438 | F27: =F26+7 -> 45312 | G27: 554.1 | H27: =G27/G26-1 -> -0.043913381 | J27: =J26+7 -> 45312 | K27: 1450 | L27: =K27/K26-1 -> -0.013101923 | N27: =N26+7 -> 45312 | O27: 387.3 | P27: =O27/O26-1 -> -0.053056235 | R27: =R26+7 -> 45312 | S27: 202.35 | T27: =S27/S26-1 -> -0.070723307 | V27: =V26+7 -> 45312 | W27: 331.28 | X27: =W27/W26-1 -> -0.033549215 | Z27: =Z26+7 -> 45312 | AA27: 21352.6 | AB27: =AA27/AA26-1 -> -0.012477801
B28: =B27+7 -> 45319 | C28: 2936.3 | D28: =C28/C27-1 -> -0.0043740675 | F28: =F27+7 -> 45319 | G28: 569.85 | H28: =G28/G27-1 -> 0.028424472 | J28: =J27+7 -> 45319 | K28: 1418.9 | L28: =K28/K27-1 -> -0.021448276 | N28: =N27+7 -> 45319 | O28: 377.85 | P28: =O28/O27-1 -> -0.02439969 | R28: =R27+7 -> 45319 | S28: 194 | T28: =S28/S27-1 -> -0.041265135 | V28: =V27+7 -> 45319 | W28: 339 | X28: =W28/W27-1 -> 0.02330355 | Z28: =Z27+7 -> 45319 | AA28: 21853.8 | AB28: =AA28/AA27-1 -> 0.023472551
B29: =B28+7 -> 45326 | C29: 2951.65 | D29: =C29/C28-1 -> 0.0052276675 | F29: =F28+7 -> 45326 | G29: 554.05 | H29: =G29/G28-1 -> -0.027726595 | J29: =J28+7 -> 45326 | K29: 1423.3 | L29: =K29/K28-1 -> 0.0031009937 | N29: =N28+7 -> 45326 | O29: 376.7 | P29: =O29/O28-1 -> -0.0030435358 | R29: =R28+7 -> 45326 | S29: 199.95 | T29: =S29/S28-1 -> 0.030670103 | V29: =V28+7 -> 45326 | W29: 315.35 | X29: =W29/W28-1 -> -0.069764012 | Z29: =Z28+7 -> 45326 | AA29: 21782.5 | AB29: =AA29/AA28-1 -> -0.0032625905
B30: =B29+7 -> 45333 | C30: 3007.9 | D30: =C30/C29-1 -> 0.019057138 | F30: =F29+7 -> 45333 | G30: 562.7 | H30: =G30/G29-1 -> 0.015612309 | J30: =J29+7 -> 45333 | K30: 1494.7 | L30: =K30/K29-1 -> 0.050165109 | N30: =N29+7 -> 45333 | O30: 369.25 | P30: =O30/O29-1 -> -0.019777011 | R30: =R29+7 -> 45333 | S30: 196.5 | T30: =S30/S29-1 -> -0.017254314 | V30: =V29+7 -> 45333 | W30: 303.05 | X30: =W30/W29-1 -> -0.039004281 | Z30: =Z29+7 -> 45333 | AA30: 22040.7 | AB30: =AA30/AA29-1 -> 0.011853552
B31: =B30+7 -> 45340 | C31: 2985.95 | D31: =C31/C30-1 -> -0.00729745 | F31: =F30+7 -> 45340 | G31: 571.8 | H31: =G31/G30-1 -> 0.016172028 | J31: =J30+7 -> 45340 | K31: 1443.5 | L31: =K31/K30-1 -> -0.034254365 | N31: =N30+7 -> 45340 | O31: 364.6 | P31: =O31/O30-1 -> -0.012593094 | R31: =R30+7 -> 45340 | S31: 195.6 | T31: =S31/S30-1 -> -0.0045801527 | V31: =V30+7 -> 45340 | W31: 300.62 | X31: =W31/W30-1 -> -0.0080184788 | Z31: =Z30+7 -> 45340 | AA31: 22212.7 | AB31: =AA31/AA30-1 -> 0.0078037449
B32: =B31+7 -> 45347 | C32: 2831.75 | D32: =C32/C31-1 -> -0.051641856 | F32: =F31+7 -> 45347 | G32: 589.05 | H32: =G32/G31-1 -> 0.030167891 | J32: =J31+7 -> 45347 | K32: 1400.95 | L32: =K32/K31-1 -> -0.029476966 | N32: =N31+7 -> 45347 | O32: 347.65 | P32: =O32/O31-1 -> -0.046489303 | R32: =R31+7 -> 45347 | S32: 172.25 | T32: =S32/S31-1 -> -0.11937628 | V32: =V31+7 -> 45347 | W32: 288.77 | X32: =W32/W31-1 -> -0.039418535 | Z32: =Z31+7 -> 45347 | AA32: 22338.75 | AB32: =AA32/AA31-1 -> 0.0056746816
B33: =B32+7 -> 45354 | C33: 2870.55 | D33: =C33/C32-1 -> 0.013701775 | F33: =F32+7 -> 45354 | G33: 573.25 | H33: =G33/G32-1 -> -0.02682285 | J33: =J32+7 -> 45354 | K33: 1363.55 | L33: =K33/K32-1 -> -0.02669617 | N33: =N32+7 -> 45354 | O33: 334.5 | P33: =O33/O32-1 -> -0.037825399 | R33: =R32+7 -> 45354 | S33: 180.4 | T33: =S33/S32-1 -> 0.047314949 | V33: =V32+7 -> 45354 | W33: 282.8 | X33: =W33/W32-1 -> -0.020673893 | Z33: =Z32+7 -> 45354 | AA33: 22493.55 | AB33: =AA33/AA32-1 -> 0.0069296626
B34: =B33+7 -> 45361 | C34: 2867.55 | D34: =C34/C33-1 -> -0.0010450959 | F34: =F33+7 -> 45361 | G34: 557.9 | H34: =G34/G33-1 -> -0.026777148 | J34: =J33+7 -> 45361 | K34: 1341.45 | L34: =K34/K33-1 -> -0.016207693 | N34: =N33+7 -> 45361 | O34: 302.5 | P34: =O34/O33-1 -> -0.095665172 | R34: =R33+7 -> 45361 | S34: 166.4 | T34: =S34/S33-1 -> -0.077605322 | V34: =V33+7 -> 45361 | W34: 270.15 | X34: =W34/W33-1 -> -0.044731259 | Z34: =Z33+7 -> 45361 | AA34: 22023.35 | AB34: =AA34/AA33-1 -> -0.02090377
B35: =B34+7 -> 45368 | C35: 2841.5 | D35: =C35/C34-1 -> -0.00908441 | F35: =F34+7 -> 45368 | G35: 558.05 | H35: =G35/G34-1 -> 0.00026886539 | J35: =J34+7 -> 45368 | K35: 1321.2 | L35: =K35/K34-1 -> -0.015095606 | N35: =N34+7 -> 45368 | O35: 299.05 | P35: =O35/O34-1 -> -0.011404959 | R35: =R34+7 -> 45368 | S35: 165 | T35: =S35/S34-1 -> -0.0084134615 | V35: =V34+7 -> 45368 | W35: 267.46 | X35: =W35/W34-1 -> -0.0099574311 | Z35: =Z34+7 -> 45368 | AA35: 22096.75 | AB35: =AA35/AA34-1 -> 0.0033328263
B36: =B35+7 -> 45375 | C36: 2846.75 | D36: =C36/C35-1 -> 0.0018476157 | F36: =F35+7 -> 45375 | G36: 572.9 | H36: =G36/G35-1 -> 0.026610519 | J36: =J35+7 -> 45375 | K36: 1256.6 | L36: =K36/K35-1 -> -0.048894944 | N36: =N35+7 -> 45375 | O36: 284.65 | P36: =O36/O35-1 -> -0.048152483 | R36: =R35+7 -> 45375 | S36: 166.1 | T36: =S36/S35-1 -> 0.0066666667 | V36: =V35+7 -> 45375 | W36: 261.09 | X36: =W36/W35-1 -> -0.023816645 | Z36: =Z35+7 -> 45375 | AA36: 22326.9 | AB36: =AA36/AA35-1 -> 0.010415559
B37: =B36+7 -> 45382 | C37: 2883.45 | D37: =C37/C36-1 -> 0.012891894 | F37: =F36+7 -> 45382 | G37: 561.8 | H37: =G37/G36-1 -> -0.019375109 | J37: =J36+7 -> 45382 | K37: 1394.65 | L37: =K37/K36-1 -> 0.10985994 | N37: =N36+7 -> 45382 | O37: 352.2 | P37: =O37/O36-1 -> 0.23730898 | R37: =R36+7 -> 45382 | S37: 176 | T37: =S37/S36-1 -> 0.059602649 | V37: =V36+7 -> 45382 | W37: 283.89 | X37: =W37/W36-1 -> 0.087326209 | Z37: =Z36+7 -> 45382 | AA37: 22513.7 | AB37: =AA37/AA36-1 -> 0.0083665892
... B111: =B110+7 -> 45900 | C111: 2579.9 | D111: =C111/C110-1 -> 0.024338918 | F111: =F110+7 -> 45900 | G111: 538.95 | H111: =G111/G110-1 -> 0.012112676 | J111: =J110+7 -> 45900 | K111: 1145.4 | L111: =K111/K110-1 -> 0.041556788 | N111: =N110+7 -> 45900 | O111: 467.75 | P111: =O111/O110-1 -> 0.01080497 | R111: =R110+7 -> 45900 | S111: 72.58 | T111: =S111/S110-1 -> 0.011849993 | V111: =V110+7 -> 45900 | W111: 242.88 | X111: =W111/W110-1 -> 0.012042168 | Z111: =Z110+7 -> 45900 | AA111: 24741 | AB111: =AA111/AA110-1 -> 0.012860848

Sheet Market Returns
B2: Nifty-50
B3: Annually Returns
B5: Year | C5: Annual
B6: 2000 | C6: -0.1465 | E6: Average Return | G6: =AVERAGE(C6:C30) -> 0.153348
B7: 2001 | C7: -0.1618 | E7: Dividend Yield | G7: 1.38% 1
B8: 2002 | C8: 0.0325 | E8: Total Market Return | G8: =SUM(G6:G7) -> 0.153348
B9: 2003 | C9: 0.719
B10: 2004 | C10: 0.1068
B11: 2005 | C11: 0.3634
B12: 2006 | C12: 0.3983
B13: 2007 | C13: 0.5477
B14: 2008 | C14: -0.5179
B15: 2009 | C15: 0.7576
B16: 2010 | C16: 0.1795
B17: 2011 | C17: -0.2462
B18: 2012 | C18: 0.277
B19: 2013 | C19: 0.0676
B20: 2014 | C20: 0.3139
... B30: 2024 | C30: 0.0875

Sheet FINANCIALS ->

Sheet FS
B4: ="Financial Statements - " & 'Profit & Loss'!A1 -> Financial Statements - ASIAN PAINTS LTD
B5: Years | D5: ='Profit & Loss'!B3 -> 42460 | E5: ='Profit & Loss'!C3 -> 42825 | F5: ='Profit & Loss'!D3 -> 43190 | G5: ='Profit & Loss'!E3 -> 43555 | H5: ='Profit & Loss'!F3 -> 43921 | I5: ='Profit & Loss'!G3 -> 44286 | J5: ='Profit & Loss'!H3 -> 44651 | K5: ='Profit & Loss'!I3 -> 45016 | ... M5: ='Profit & Loss'!K3 -> 45747
A7: # | B7: ="Income Statement - " &'Data Sheet'!$B$1 -> Income Statement - ASIAN PAINTS LTD
B9: Sales | D9: =IFERROR('Profit & Loss'!B4,0) -> 14271.49 | E9: =IFERROR('Profit & Loss'!C4,0) -> 15061.99 | F9: =IFERROR('Profit & Loss'!D4,0) -> 16824.55 | G9: =IFERROR('Profit & Loss'!E4,0) -> 19240.13 | H9: =IFERROR('Profit & Loss'!F4,0) -> 20211.25 | I9: =IFERROR('Profit & Loss'!G4,0) -> 21712.79 | J9: =IFERROR('Profit & Loss'!H4,0) -> 29101.28 | K9: =IFERROR('Profit & Loss'!I4,0) -> 34488.59 | ... M9: =IFERROR('Profit & Loss'!K4,0) -> 33905.62
B10: Sales Growth | D10: - | E10: =IFERROR(E9/D9-1,0) -> 0.055390152 | F10: =IFERROR(F9/E9-1,0) -> 0.11702039 | G10: =IFERROR(G9/F9-1,0) -> 0.14357472 | H10: =IFERROR(H9/G9-1,0) -> 0.050473671 | I10: =IFERROR(I9/H9-1,0) -> 0.074292288 | J10: =IFERROR(J9/I9-1,0) -> 0.34028285 | K10: =IFERROR(K9/J9-1,0) -> 0.18512278 | L10: =IFERROR(L9/K9-1,0) -> 0.029173127 | M10: =IFERROR(M9/L9-1,0) -> -0.044770308
B12: COGS | D12: =IFERROR(SUM('Data Sheet'!B18,1*('Data Sheet'!B19),'Data Sheet'!B21),0) -> 7905.72 | E12: =IFERROR(SUM('Data Sheet'!C18,-1*('Data Sheet'!C19),'Data Sheet'!C20,'Data Sheet'!C21),0) -> 8692.77 | F12: =IFERROR(SUM('Data Sheet'!D18,-1*('Data Sheet'!D19),'Data Sheet'!D20,'Data Sheet'!D21),0) -> 10072.28 | G12: =IFERROR(SUM('Data Sheet'!E18,-1*('Data Sheet'!E19),'Data Sheet'!E20,'Data Sheet'!E21),0) -> 11663.12 | H12: =IFERROR(SUM('Data Sheet'!F18,-1*('Data Sheet'!F19),'Data Sheet'!F20,'Data Sheet'!F21),0) -> 11786.75 | I12: =IFERROR(SUM('Data Sheet'!G18,-1*('Data Sheet'!G19),'Data Sheet'!G20,'Data Sheet'!G21),0) -> 12487.46 | J12: =IFERROR(SUM('Data Sheet'!H18,-1*('Data Sheet'!H19),'Data Sheet'!H20,'Data Sheet'!H21),0) -> 18795.96 | K12: =IFERROR(SUM('Data Sheet'!I18,-1*('Data Sheet'!I19),'Data Sheet'!I20,'Data Sheet'!I21),0) -> 21730.29 | L12: =IFERROR(SUM('Data Sheet'!J18,-1*('Data Sheet'!J19),'Data Sheet'!J20,'Data Sheet'!J21),0) -> 20675.07 | M12: =IFERROR(SUM('Data Sheet'!K18,-1*('Data Sheet'!K19),'Data Sheet'!K20,'Data Sheet'!K21),0) -> 20135.49
B13: COGS as % of Sales | D13: =IFERROR(D12/D9,0) -> 0.55395197 | E13: =IFERROR(E12/E9,0) -> 0.5771329 | F13: =IFERROR(F12/F9,0) -> 0.59866564 | G13: =IFERROR(G12/G9,0) -> 0.60618717 | H13: =IFERROR(H12/H9,0) -> 0.58317769 | I13: =IFERROR(I12/I9,0) -> 0.57512001 | J13: =IFERROR(J12/J9,0) -> 0.64588087 | K13: =IFERROR(K12/K9,0) -> 0.63007186 | ... M13: =IFERROR(M12/M9,0) -> 0.5938688
B15: Gross Profit | D15: =IFERROR(D9-D12,0) -> 6365.77 | E15: =IFERROR(E9-E12,0) -> 6369.22 | F15: =IFERROR(F9-F12,0) -> 6752.27 | G15: =IFERROR(G9-G12,0) -> 7577.01 | H15: =IFERROR(H9-H12,0) -> 8424.5 | I15: =IFERROR(I9-I12,0) -> 9225.33 | J15: =IFERROR(J9-J12,0) -> 10305.32 | K15: =IFERROR(K9-K12,0) -> 12758.3 | ... M15: =IFERROR(M9-M12,0) -> 13770.13
B16: Gross Margin | D16: =IFERROR(D15/D9,0) -> 0.44604803 | E16: =IFERROR(E15/E9,0) -> 0.4228671 | F16: =IFERROR(F15/F9,0) -> 0.40133436 | G16: =IFERROR(G15/G9,0) -> 0.39381283 | H16: =IFERROR(H15/H9,0) -> 0.41682231 | I16: =IFERROR(I15/I9,0) -> 0.42487999 | J16: =IFERROR(J15/J9,0) -> 0.35411913 | K16: =IFERROR(K15/K9,0) -> 0.36992814 | ... M16: =IFERROR(M15/M9,0) -> 0.4061312
B18: S&G Expenses | D18: =IFERROR('Data Sheet'!B23-'Data Sheet'!B25,0) -> 3698.91 | E18: =IFERROR('Data Sheet'!C23-'Data Sheet'!C25,0) -> 4026.14 | F18: =IFERROR('Data Sheet'!D23-'Data Sheet'!D25,0) -> 1918.51 | G18: =IFERROR('Data Sheet'!E23-'Data Sheet'!E25,0) -> 2093.1 | H18: =IFERROR('Data Sheet'!F23-'Data Sheet'!F25,0) -> 1956.46 | I18: =IFERROR('Data Sheet'!G23-'Data Sheet'!G25,0) -> 1914.04 | J18: =IFERROR('Data Sheet'!H23-'Data Sheet'!H25,0) -> 2646.1 | K18: =IFERROR('Data Sheet'!I23-'Data Sheet'!I25,0) -> 3069.38 | ... M18: =IFERROR('Data Sheet'!K23-'Data Sheet'!K25,0) -> 3524.72
B19: S&A Expenses as % of Sales | D19: =IFERROR(D18/D9,0) -> 0.25918177 | E19: =IFERROR(E18/E9,0) -> 0.26730465 | F19: =IFERROR(F18/F9,0) -> 0.11403039 | G19: =IFERROR(G18/G9,0) -> 0.10878825 | H19: =IFERROR(H18/H9,0) -> 0.096800544 | I19: =IFERROR(I18/I9,0) -> 0.088152651 | J19: =IFERROR(J18/J9,0) -> 0.090927272 | K19: =IFERROR(K18/K9,0) -> 0.08899697 | ... M19: =IFERROR(M18/M9,0) -> 0.10395681
B21: EBITDA | D21: =IFERROR('Profit & Loss'!B6,0) -> 2725.04 | E21: =IFERROR('Profit & Loss'!C6,0) -> 2993.76 | F21: =IFERROR('Profit & Loss'!D6,0) -> 3204.01 | G21: =IFERROR('Profit & Loss'!E6,0) -> 3764.94 | H21: =IFERROR('Profit & Loss'!F6,0) -> 4156.82 | I21: =IFERROR('Profit & Loss'!G6,0) -> 4855.6 | J21: =IFERROR('Profit & Loss'!H6,0) -> 4803.61 | K21: =IFERROR('Profit & Loss'!I6,0) -> 6259.84 | ... M21: =IFERROR('Profit & Loss'!K6,0) -> 6006.21
B22: EBITDA Margin | D22: =IFERROR(D21/D9,0) -> 0.19094292 | E22: =IFERROR(E21/E9,0) -> 0.19876258 | F22: =IFERROR(F21/F9,0) -> 0.19043659 | G22: =IFERROR(G21/G9,0) -> 0.19568163 | H22: =IFERROR(H21/H9,0) -> 0.20566863 | I22: =IFERROR(I21/I9,0) -> 0.22362856 | J22: =IFERROR(J21/J9,0) -> 0.16506525 | K22: =IFERROR(K21/K9,0) -> 0.18150467 | ... M22: =IFERROR(M21/M9,0) -> 0.17714497
B24: Depriciation | D24: ='Profit & Loss'!B8 -> 275.58 | E24: ='Profit & Loss'!C8 -> 334.79 | F24: ='Profit & Loss'!D8 -> 360.47 | G24: ='Profit & Loss'!E8 -> 622.14 | H24: ='Profit & Loss'!F8 -> 780.5 | I24: ='Profit & Loss'!G8 -> 791.27 | J24: ='Profit & Loss'!H8 -> 816.36 | K24: ='Profit & Loss'!I8 -> 858.02 | ... M24: ='Profit & Loss'!K8 -> 1026.34
B25: Depriciation as % of sales | D25: =D24/D9 -> 0.019309827 | E25: =E24/E9 -> 0.022227475 | F25: =F24/F9 -> 0.021425239 | G25: =G24/G9 -> 0.03233554 | H25: =H24/H9 -> 0.038617107 | I25: =I24/I9 -> 0.036442576 | J25: =J24/J9 -> 0.028052374 | K25: =K24/K9 -> 0.024878373 | ... M25: =M24/M9 -> 0.030270498
